[2024-12-06T11:29:14.350+0000] {taskinstance.py:1103} INFO - Dependencies all met for dep_context=non-requeueable deps ti=<TaskInstance: etl_pipeline_dag.run_etl_pipeline manual__2024-12-06T11:29:13.066908+00:00 [queued]>
[2024-12-06T11:29:14.354+0000] {taskinstance.py:1103} INFO - Dependencies all met for dep_context=requeueable deps ti=<TaskInstance: etl_pipeline_dag.run_etl_pipeline manual__2024-12-06T11:29:13.066908+00:00 [queued]>
[2024-12-06T11:29:14.354+0000] {taskinstance.py:1308} INFO - Starting attempt 1 of 2
[2024-12-06T11:29:14.360+0000] {taskinstance.py:1327} INFO - Executing <Task(PythonOperator): run_etl_pipeline> on 2024-12-06 11:29:13.066908+00:00
[2024-12-06T11:29:14.363+0000] {standard_task_runner.py:57} INFO - Started process 221 to run task
[2024-12-06T11:29:14.365+0000] {standard_task_runner.py:84} INFO - Running: ['airflow', 'tasks', 'run', 'etl_pipeline_dag', 'run_etl_pipeline', 'manual__2024-12-06T11:29:13.066908+00:00', '--job-id', '14', '--raw', '--subdir', 'DAGS_FOLDER/etl_pipeline_dag.py', '--cfg-path', '/tmp/tmprjydrhim']
[2024-12-06T11:29:14.366+0000] {standard_task_runner.py:85} INFO - Job 14: Subtask run_etl_pipeline
[2024-12-06T11:29:14.395+0000] {task_command.py:410} INFO - Running <TaskInstance: etl_pipeline_dag.run_etl_pipeline manual__2024-12-06T11:29:13.066908+00:00 [running]> on host 17cb5735e503
[2024-12-06T11:29:14.446+0000] {taskinstance.py:1547} INFO - Exporting env vars: AIRFLOW_CTX_DAG_OWNER='airflow' AIRFLOW_CTX_DAG_ID='etl_pipeline_dag' AIRFLOW_CTX_TASK_ID='run_etl_pipeline' AIRFLOW_CTX_EXECUTION_DATE='2024-12-06T11:29:13.066908+00:00' AIRFLOW_CTX_TRY_NUMBER='1' AIRFLOW_CTX_DAG_RUN_ID='manual__2024-12-06T11:29:13.066908+00:00'
[2024-12-06T11:29:14.447+0000] {logging_mixin.py:150} INFO - Starting ETL pipeline...
[2024-12-06T11:29:14.447+0000] {logging_mixin.py:150} INFO - Extracting data...
[2024-12-06T11:29:14.453+0000] {logging_mixin.py:150} INFO - ETL pipeline failed: (psycopg2.errors.SyntaxError) syntax error at or near "order"
LINE 1: SELECT * FROM order
                      ^

[SQL: SELECT * FROM order]
(Background on this error at: https://sqlalche.me/e/14/f405)
[2024-12-06T11:29:14.453+0000] {python.py:183} INFO - Done. Returned value was: None
[2024-12-06T11:29:14.460+0000] {taskinstance.py:1350} INFO - Marking task as SUCCESS. dag_id=etl_pipeline_dag, task_id=run_etl_pipeline, execution_date=20241206T112913, start_date=20241206T112914, end_date=20241206T112914
[2024-12-06T11:29:14.508+0000] {local_task_job_runner.py:225} INFO - Task exited with return code 0
[2024-12-06T11:29:14.522+0000] {taskinstance.py:2653} INFO - 0 downstream tasks scheduled from follow-on schedule check
