[2024-12-06T11:28:21.512+0000] {taskinstance.py:1103} INFO - Dependencies all met for dep_context=non-requeueable deps ti=<TaskInstance: etl_pipeline_dag.run_etl_pipeline manual__2024-12-06T11:28:20.316135+00:00 [queued]>
[2024-12-06T11:28:21.516+0000] {taskinstance.py:1103} INFO - Dependencies all met for dep_context=requeueable deps ti=<TaskInstance: etl_pipeline_dag.run_etl_pipeline manual__2024-12-06T11:28:20.316135+00:00 [queued]>
[2024-12-06T11:28:21.516+0000] {taskinstance.py:1308} INFO - Starting attempt 1 of 2
[2024-12-06T11:28:21.523+0000] {taskinstance.py:1327} INFO - Executing <Task(PythonOperator): run_etl_pipeline> on 2024-12-06 11:28:20.316135+00:00
[2024-12-06T11:28:21.526+0000] {standard_task_runner.py:57} INFO - Started process 185 to run task
[2024-12-06T11:28:21.528+0000] {standard_task_runner.py:84} INFO - Running: ['airflow', 'tasks', 'run', 'etl_pipeline_dag', 'run_etl_pipeline', 'manual__2024-12-06T11:28:20.316135+00:00', '--job-id', '13', '--raw', '--subdir', 'DAGS_FOLDER/etl_pipeline_dag.py', '--cfg-path', '/tmp/tmp0olntj2q']
[2024-12-06T11:28:21.529+0000] {standard_task_runner.py:85} INFO - Job 13: Subtask run_etl_pipeline
[2024-12-06T11:28:21.561+0000] {task_command.py:410} INFO - Running <TaskInstance: etl_pipeline_dag.run_etl_pipeline manual__2024-12-06T11:28:20.316135+00:00 [running]> on host 17cb5735e503
[2024-12-06T11:28:21.614+0000] {taskinstance.py:1547} INFO - Exporting env vars: AIRFLOW_CTX_DAG_OWNER='airflow' AIRFLOW_CTX_DAG_ID='etl_pipeline_dag' AIRFLOW_CTX_TASK_ID='run_etl_pipeline' AIRFLOW_CTX_EXECUTION_DATE='2024-12-06T11:28:20.316135+00:00' AIRFLOW_CTX_TRY_NUMBER='1' AIRFLOW_CTX_DAG_RUN_ID='manual__2024-12-06T11:28:20.316135+00:00'
[2024-12-06T11:28:21.615+0000] {logging_mixin.py:150} INFO - Starting ETL pipeline...
[2024-12-06T11:28:21.615+0000] {logging_mixin.py:150} INFO - Extracting data...
[2024-12-06T11:28:21.621+0000] {logging_mixin.py:150} INFO - ETL pipeline failed: (psycopg2.errors.UndefinedTable) relation "order" does not exist
LINE 1: SELECT * FROM "order"
                      ^

[SQL: SELECT * FROM "order"]
(Background on this error at: https://sqlalche.me/e/14/f405)
[2024-12-06T11:28:21.621+0000] {python.py:183} INFO - Done. Returned value was: None
[2024-12-06T11:28:21.627+0000] {taskinstance.py:1350} INFO - Marking task as SUCCESS. dag_id=etl_pipeline_dag, task_id=run_etl_pipeline, execution_date=20241206T112820, start_date=20241206T112821, end_date=20241206T112821
[2024-12-06T11:28:21.672+0000] {local_task_job_runner.py:225} INFO - Task exited with return code 0
[2024-12-06T11:28:21.683+0000] {taskinstance.py:2653} INFO - 0 downstream tasks scheduled from follow-on schedule check
