[2025-02-14T06:22:13.877+0000] {local_task_job_runner.py:123} INFO - ::group::Pre task execution logs
[2025-02-14T06:22:13.884+0000] {taskinstance.py:2614} INFO - Dependencies all met for dep_context=non-requeueable deps ti=<TaskInstance: etl_pipeline_dag.run_etl_pipeline manual__2025-02-14T06:17:09.170702+00:00 [queued]>
[2025-02-14T06:22:13.888+0000] {taskinstance.py:2614} INFO - Dependencies all met for dep_context=requeueable deps ti=<TaskInstance: etl_pipeline_dag.run_etl_pipeline manual__2025-02-14T06:17:09.170702+00:00 [queued]>
[2025-02-14T06:22:13.889+0000] {taskinstance.py:2867} INFO - Starting attempt 2 of 2
[2025-02-14T06:22:13.894+0000] {taskinstance.py:2890} INFO - Executing <Task(PythonOperator): run_etl_pipeline> on 2025-02-14 06:17:09.170702+00:00
[2025-02-14T06:22:13.902+0000] {standard_task_runner.py:104} INFO - Running: ['***', 'tasks', 'run', 'etl_pipeline_dag', 'run_etl_pipeline', 'manual__2025-02-14T06:17:09.170702+00:00', '--job-id', '10', '--raw', '--subdir', 'DAGS_FOLDER/etl_pipeline_dag.py', '--cfg-path', '/tmp/tmp2y0r8yui']
[2025-02-14T06:22:13.908+0000] {standard_task_runner.py:105} INFO - Job 10: Subtask run_etl_pipeline
[2025-02-14T06:22:13.912+0000] {logging_mixin.py:190} WARNING - /home/***/.local/lib/python3.12/site-packages/***/task/task_runner/standard_task_runner.py:70 DeprecationWarning: This process (pid=278) is multi-threaded, use of fork() may lead to deadlocks in the child.
[2025-02-14T06:22:13.914+0000] {standard_task_runner.py:72} INFO - Started process 279 to run task
[2025-02-14T06:22:13.954+0000] {task_command.py:467} INFO - Running <TaskInstance: etl_pipeline_dag.run_etl_pipeline manual__2025-02-14T06:17:09.170702+00:00 [running]> on host 03b77893a9ac
[2025-02-14T06:22:14.003+0000] {taskinstance.py:3134} INFO - Exporting env vars: AIRFLOW_CTX_DAG_OWNER='***' AIRFLOW_CTX_DAG_ID='etl_pipeline_dag' AIRFLOW_CTX_TASK_ID='run_etl_pipeline' AIRFLOW_CTX_EXECUTION_DATE='2025-02-14T06:17:09.170702+00:00' AIRFLOW_CTX_TRY_NUMBER='2' AIRFLOW_CTX_DAG_RUN_ID='manual__2025-02-14T06:17:09.170702+00:00'
[2025-02-14T06:22:14.006+0000] {taskinstance.py:732} INFO - ::endgroup::
[2025-02-14T06:22:14.018+0000] {logging_mixin.py:190} INFO - Starting ETL pipeline...
[2025-02-14T06:22:14.020+0000] {logging_mixin.py:190} INFO - Extracting data...
[2025-02-14T06:25:10.984+0000] {logging_mixin.py:190} INFO - Detected file encoding: ISO-8859-1
[2025-02-14T06:25:11.511+0000] {logging_mixin.py:190} INFO - Data extracted successfully!
[2025-02-14T06:25:11.511+0000] {logging_mixin.py:190} INFO - Transforming data...
[2025-02-14T06:25:11.514+0000] {logging_mixin.py:190} INFO - ETL pipeline failed: 'date'
[2025-02-14T06:25:11.516+0000] {taskinstance.py:3313} ERROR - Task failed with exception
Traceback (most recent call last):
  File "/home/airflow/.local/lib/python3.12/site-packages/pandas/core/indexes/base.py", line 3791, in get_loc
    return self._engine.get_loc(casted_key)
           ^^^^^^^^^^^^^^^^^^^^^^^^^^^^^^^^
  File "index.pyx", line 152, in pandas._libs.index.IndexEngine.get_loc
  File "index.pyx", line 181, in pandas._libs.index.IndexEngine.get_loc
  File "pandas/_libs/hashtable_class_helper.pxi", line 7080, in pandas._libs.hashtable.PyObjectHashTable.get_item
  File "pandas/_libs/hashtable_class_helper.pxi", line 7088, in pandas._libs.hashtable.PyObjectHashTable.get_item
KeyError: 'date'

The above exception was the direct cause of the following exception:

Traceback (most recent call last):
  File "/home/airflow/.local/lib/python3.12/site-packages/airflow/models/taskinstance.py", line 768, in _execute_task
    result = _execute_callable(context=context, **execute_callable_kwargs)
             ^^^^^^^^^^^^^^^^^^^^^^^^^^^^^^^^^^^^^^^^^^^^^^^^^^^^^^^^^^^^^
  File "/home/airflow/.local/lib/python3.12/site-packages/airflow/models/taskinstance.py", line 734, in _execute_callable
    return ExecutionCallableRunner(
           ^^^^^^^^^^^^^^^^^^^^^^^^
  File "/home/airflow/.local/lib/python3.12/site-packages/airflow/utils/operator_helpers.py", line 252, in run
    return self.func(*args, **kwargs)
           ^^^^^^^^^^^^^^^^^^^^^^^^^^
  File "/home/airflow/.local/lib/python3.12/site-packages/airflow/models/baseoperator.py", line 424, in wrapper
    return func(self, *args, **kwargs)
           ^^^^^^^^^^^^^^^^^^^^^^^^^^^
  File "/home/airflow/.local/lib/python3.12/site-packages/airflow/operators/python.py", line 238, in execute
    return_value = self.execute_callable()
                   ^^^^^^^^^^^^^^^^^^^^^^^
  File "/home/airflow/.local/lib/python3.12/site-packages/airflow/operators/python.py", line 256, in execute_callable
    return runner.run(*self.op_args, **self.op_kwargs)
           ^^^^^^^^^^^^^^^^^^^^^^^^^^^^^^^^^^^^^^^^^^^
  File "/home/airflow/.local/lib/python3.12/site-packages/airflow/utils/operator_helpers.py", line 252, in run
    return self.func(*args, **kwargs)
           ^^^^^^^^^^^^^^^^^^^^^^^^^^
  File "/opt/airflow/scripts/etl_pipeline.py", line 100, in run_etl_script
    # 고객 요약 테이블에 데이터 저장
                               ^^^^^^
  File "/opt/airflow/scripts/etl_pipeline.py", line 46, in transform_data
    'Description': 'product_name',
                            ^^^^^^^
  File "/home/airflow/.local/lib/python3.12/site-packages/pandas/core/frame.py", line 3893, in __getitem__
    indexer = self.columns.get_loc(key)
              ^^^^^^^^^^^^^^^^^^^^^^^^^
  File "/home/airflow/.local/lib/python3.12/site-packages/pandas/core/indexes/base.py", line 3798, in get_loc
    raise KeyError(key) from err
KeyError: 'date'
[2025-02-14T06:25:11.542+0000] {taskinstance.py:1226} INFO - Marking task as FAILED. dag_id=etl_pipeline_dag, task_id=run_etl_pipeline, run_id=manual__2025-02-14T06:17:09.170702+00:00, execution_date=20250214T061709, start_date=20250214T062213, end_date=20250214T062511
[2025-02-14T06:25:11.561+0000] {taskinstance.py:341} INFO - ::group::Post task execution logs
[2025-02-14T06:25:11.562+0000] {standard_task_runner.py:124} ERROR - Failed to execute job 10 for task run_etl_pipeline ('date'; 279)
Traceback (most recent call last):
  File "/home/airflow/.local/lib/python3.12/site-packages/pandas/core/indexes/base.py", line 3791, in get_loc
    return self._engine.get_loc(casted_key)
           ^^^^^^^^^^^^^^^^^^^^^^^^^^^^^^^^
  File "index.pyx", line 152, in pandas._libs.index.IndexEngine.get_loc
  File "index.pyx", line 181, in pandas._libs.index.IndexEngine.get_loc
  File "pandas/_libs/hashtable_class_helper.pxi", line 7080, in pandas._libs.hashtable.PyObjectHashTable.get_item
  File "pandas/_libs/hashtable_class_helper.pxi", line 7088, in pandas._libs.hashtable.PyObjectHashTable.get_item
KeyError: 'date'

The above exception was the direct cause of the following exception:

Traceback (most recent call last):
  File "/home/airflow/.local/lib/python3.12/site-packages/airflow/task/task_runner/standard_task_runner.py", line 117, in _start_by_fork
    ret = args.func(args, dag=self.dag)
          ^^^^^^^^^^^^^^^^^^^^^^^^^^^^^
  File "/home/airflow/.local/lib/python3.12/site-packages/airflow/cli/cli_config.py", line 49, in command
    return func(*args, **kwargs)
           ^^^^^^^^^^^^^^^^^^^^^
  File "/home/airflow/.local/lib/python3.12/site-packages/airflow/utils/cli.py", line 116, in wrapper
    return f(*args, **kwargs)
           ^^^^^^^^^^^^^^^^^^
  File "/home/airflow/.local/lib/python3.12/site-packages/airflow/cli/commands/task_command.py", line 483, in task_run
    task_return_code = _run_task_by_selected_method(args, _dag, ti)
                       ^^^^^^^^^^^^^^^^^^^^^^^^^^^^^^^^^^^^^^^^^^^^
  File "/home/airflow/.local/lib/python3.12/site-packages/airflow/cli/commands/task_command.py", line 256, in _run_task_by_selected_method
    return _run_raw_task(args, ti)
           ^^^^^^^^^^^^^^^^^^^^^^^
  File "/home/airflow/.local/lib/python3.12/site-packages/airflow/cli/commands/task_command.py", line 341, in _run_raw_task
    return ti._run_raw_task(
           ^^^^^^^^^^^^^^^^^
  File "/home/airflow/.local/lib/python3.12/site-packages/airflow/utils/session.py", line 97, in wrapper
    return func(*args, session=session, **kwargs)
           ^^^^^^^^^^^^^^^^^^^^^^^^^^^^^^^^^^^^^^
  File "/home/airflow/.local/lib/python3.12/site-packages/airflow/models/taskinstance.py", line 3006, in _run_raw_task
    return _run_raw_task(
           ^^^^^^^^^^^^^^
  File "/home/airflow/.local/lib/python3.12/site-packages/airflow/models/taskinstance.py", line 274, in _run_raw_task
    TaskInstance._execute_task_with_callbacks(
  File "/home/airflow/.local/lib/python3.12/site-packages/airflow/models/taskinstance.py", line 3161, in _execute_task_with_callbacks
    result = self._execute_task(context, task_orig)
             ^^^^^^^^^^^^^^^^^^^^^^^^^^^^^^^^^^^^^^
  File "/home/airflow/.local/lib/python3.12/site-packages/airflow/models/taskinstance.py", line 3185, in _execute_task
    return _execute_task(self, context, task_orig)
           ^^^^^^^^^^^^^^^^^^^^^^^^^^^^^^^^^^^^^^^
  File "/home/airflow/.local/lib/python3.12/site-packages/airflow/models/taskinstance.py", line 768, in _execute_task
    result = _execute_callable(context=context, **execute_callable_kwargs)
             ^^^^^^^^^^^^^^^^^^^^^^^^^^^^^^^^^^^^^^^^^^^^^^^^^^^^^^^^^^^^^
  File "/home/airflow/.local/lib/python3.12/site-packages/airflow/models/taskinstance.py", line 734, in _execute_callable
    return ExecutionCallableRunner(
           ^^^^^^^^^^^^^^^^^^^^^^^^
  File "/home/airflow/.local/lib/python3.12/site-packages/airflow/utils/operator_helpers.py", line 252, in run
    return self.func(*args, **kwargs)
           ^^^^^^^^^^^^^^^^^^^^^^^^^^
  File "/home/airflow/.local/lib/python3.12/site-packages/airflow/models/baseoperator.py", line 424, in wrapper
    return func(self, *args, **kwargs)
           ^^^^^^^^^^^^^^^^^^^^^^^^^^^
  File "/home/airflow/.local/lib/python3.12/site-packages/airflow/operators/python.py", line 238, in execute
    return_value = self.execute_callable()
                   ^^^^^^^^^^^^^^^^^^^^^^^
  File "/home/airflow/.local/lib/python3.12/site-packages/airflow/operators/python.py", line 256, in execute_callable
    return runner.run(*self.op_args, **self.op_kwargs)
           ^^^^^^^^^^^^^^^^^^^^^^^^^^^^^^^^^^^^^^^^^^^
  File "/home/airflow/.local/lib/python3.12/site-packages/airflow/utils/operator_helpers.py", line 252, in run
    return self.func(*args, **kwargs)
           ^^^^^^^^^^^^^^^^^^^^^^^^^^
  File "/opt/airflow/scripts/etl_pipeline.py", line 100, in run_etl_script
    # 고객 요약 테이블에 데이터 저장
                               ^^^^^^
  File "/opt/airflow/scripts/etl_pipeline.py", line 46, in transform_data
    'Description': 'product_name',
                            ^^^^^^^
  File "/home/airflow/.local/lib/python3.12/site-packages/pandas/core/frame.py", line 3893, in __getitem__
    indexer = self.columns.get_loc(key)
              ^^^^^^^^^^^^^^^^^^^^^^^^^
  File "/home/airflow/.local/lib/python3.12/site-packages/pandas/core/indexes/base.py", line 3798, in get_loc
    raise KeyError(key) from err
KeyError: 'date'
[2025-02-14T06:25:11.606+0000] {local_task_job_runner.py:266} INFO - Task exited with return code 1
[2025-02-14T06:25:11.618+0000] {taskinstance.py:3901} INFO - 0 downstream tasks scheduled from follow-on schedule check
[2025-02-14T06:25:11.619+0000] {local_task_job_runner.py:245} INFO - ::endgroup::
